앞선 강의에서, `docker-compose` 사용 시, DB의 로딩으로 인한 경쟁상황에 대하여 서술한 바 있다.
이를 해결하기 위해 DB_COMMAND 를 기다리는 앱을 작성하려고 한다.
1. `docker-compose run --rm app sh -c "python manage.py startapp core"`
2. `views.py`, `tests.py`  삭제
3. core > management > commands 생성 (*각 폴더마다 `__init__.py`) 생성
```bash
# 폴더 트리
core
|-- __init__.py
|-- admin.py
|-- apps.py
|-- management
|   |-- __init__.py
|   `-- commands
|       |-- __init__.py
|       `-- wait_for_db.py
|-- migrations
|   |-- __init__.py
|-- models.py
`-- tests
    |-- __init__.py
    `-- test_commands.py
```
4. `wait_for_db.py` 작성 (* [참고](https://docs.djangoproject.com/en/3.2/howto/custom-management-commands/))
```python
# core
# |-- management/
# |    `-- commands/
# |       `-- wait_for_db.py
"""
DB를 사용할 수 있을때 까지 기다리는 django command
"""

from django.core.management.base import BaseCommand

class Command(BaseCommand):
    """DB를 사용할 수 있을때 까지 기다리는 django command"""

    def handle(self, *args, **options):
        pass
```
5. `test_commands.py`  작성
```python
# core
# |-- management/
# |    `-- tests/
# |       `-- test_commands.py
"""
Command 테스트
"""
 
from unittest.mock import patch

from psycopg2 import OperationalError as Psycopg2Error

  
from django.core.management import call_command
from django.db.utils import OperationalError
from django.test import SimpleTestCase

@patch("core.management.commands.wait_for_db.Command.check")
class CommandTests(SimpleTestCase):
    """Command 테스트"""
  
    def test_wait_for_db_ready(self, patched_check):
        """대기 테스트"""
        patched_check.return_value = True
  
        call_command('wait_for_db')

        patched_check.assert_called_once_with(database=['default'])
  
    @patch('time.sleep')
    def test_wait_for_db_delay(self, patched_sleep, patched_check):
        """Test waiting for DB when getting OperationalError"""
        patched_check.side_effect = [Psycopg2Error] * 2 + \
            [OperationalError] * 3 + [True]

        call_command('wait_for_db')

        self.assertEqual(patched_check.call_count, 6)

        patched_check.assert_called_with(database=['default'])

```
- `patch`  | we need on the imports patch
in order to mock behavior.
We're going to mock the behavior of the database because we need to be able to simulate when the database
is returning a response or not.
- `Psycopg2Error` | then we have this operational error exception, which we import from psychology to.
It's one of the possibilities of the errors that we might get when we try and connect to the database before the database is ready.
- `call_command` |  Then we have the call command, which is a helper function provided by Django that allows us to simulate or to actually call a command by the name. And this allows us to actually call the command that we're testing.
- `OperationalError` |  And then we have another operational error, which is another exception that may get thrown by the database depending on what stage of the start up process it is.
- `SimpleTestCase` |  And we basically want to cover both options. And then we have a simple test case, which is the base test course that we're going to use for testing out our unit test or creating our unit test. And it's important that we use a simple test case because we are testing behavior that the database is not available and therefore we do not need migrations and things like that to be applied to the test database because we're just actually simulating behavior of that database. So we're just going to use simple test case so it doesn't create any database set up and things like that behind the scenes.
6. `CommandTests`
```python

```

7. 결과
```bash

$ docker-compose run --rm app sh -c "python manage.py test"
[+] Running 1/0
 - Container api-prac-db-1  Running                      0.0s
System check identified no issues (0 silenced).
..FF
======================================================================
FAIL: test_wait_for_db_delay (core.tests.test_commands.CommandTests)
Test waiting for DB when getting OperationalError
----------------------------------------------------------------------
Traceback (most recent call last):
  File "/usr/local/lib/python3.9/unittest/mock.py", line 1336, in patched
    return func(*newargs, **newkeywargs)
  File "/app/core/tests/test_commands.py", line 33, in test_wait_for_db_delay
    self.assertEqual(patched_check.call_count, 6)
AssertionError: 0 != 6

======================================================================
FAIL: test_wait_for_db_ready (core.tests.test_commands.CommandTests)
Test waiting for DB if DB ready
----------------------------------------------------------------------
Traceback (most recent call last):
  File "/usr/local/lib/python3.9/unittest/mock.py", line 1336, in patched
    return func(*newargs, **newkeywargs)
  File "/app/core/tests/test_commands.py", line 23, in test_wait_for_db_ready
    patched_check.assert_called_once_with(database=['default'])
  File "/usr/local/lib/python3.9/unittest/mock.py", line 918, in assert_called_once_with
    raise AssertionError(msg)
AssertionError: Expected 'check' to be called once. Called 0 times.

----------------------------------------------------------------------
Ran 4 tests in 0.019s

FAILED (failures=2)
```