```python
from django.test import TestCase
from django.contrib.auth import get_user_model

  
class ModelTests(TestCase):
    """Test models"""

    def test_create_user_with_email_successful(self):

        email = 'test@example.com'
        password = 'testpass123'
        user = get_user_model().objects.create_user(
            email=email,
            password=password,
        )

        self.assertEqual(user.email, email)
        self.assertTrue(user.check_password(password))

```
```bash
$ docker compose run --rm app sh -c "python manage.py test"
[+] Running 1/0
 - Container api-prac-db-1  Running                      0.0s
Creating test database for alias 'default'...
System check identified no issues (0 silenced).
E..Waitng for database ...
Database unvailable, waiting 1 second ...
Database unvailable, waiting 1 second ...
Database unvailable, waiting 1 second ...
Database unvailable, waiting 1 second ...
Database unvailable, waiting 1 second ...
Database available !
.Waitng for database ...
Database available !
.
======================================================================
ERROR: test_create_user_with_email_successful (core.tests.test_models.ModelTests)
----------------------------------------------------------------------
Traceback (most recent call last):
  File "/app/core/tests/test_models.py", line 14, in test_create_user_with_email_successful
    user = get_user_model().objects.create_user(
TypeError: create_user() missing 1 required positional argument: 'username'

----------------------------------------------------------------------
Ran 5 tests in 0.036s

FAILED (errors=1)
Destroying test database for alias 'default'...
(base) 
```