```python
"""
Tests for the Django admin modifications.
"""

from django.test import TestCase
from django.contrib.auth import get_user_model
from django.urls import reverse
from django.test import Client


class AdminSiteTests(TestCase):
    """Tests for Django admin."""
    
    def setUp(self):
        """Create user and client."""
        self.client = Client()
        self.admin_user = get_user_model().objects.create_superuser(
            email = 'user@example.com',
            password = 'testpass'
        )
        self.client.force_login(self.admin_user)
        self.user = get_user_model().objects.create_user(
            email='user@example.com',
            password = 'testpass',
            name = 'Test User'
        )

    def test_user_list(self):
        """Test that users are listed on page."""
        url = reverse('admin:core_user_chagelist')
        res = self.client.get(url)

        self.assertContains(res, self.user.name)
        self.assertContains(res, self.user.email)
```

```bash
$ docker-compose run --rm app sh -c "python manage.py test"
[+] Running 1/0
 - Container api-prac-db-1  Running                     0.0s 
Creating test database for alias 'default'...
System check identified no issues (0 silenced).
E......Waitng for database ...
Database unvailable, waiting 1 second ...
Database unvailable, waiting 1 second ...
Database unvailable, waiting 1 second ...
Database unvailable, waiting 1 second ...
Database unvailable, waiting 1 second ...
Database available !
.Waitng for database ...
Database available !
.
======================================================================
ERROR: test_user_list (core.tests.test_admin.AdminSiteTests) 
Test that users are listed on page.
----------------------------------------------------------------------
Traceback (most recent call last):
  File "/app/core/tests/test_admin.py", line 29, in test_user_list
    url = reverse('admin:core_user_chagelist')
  File "/py/lib/python3.9/site-packages/django/urls/base.py", line 86, in reverse
    return resolver._reverse_with_prefix(view, prefix, *args, **kwargs)
  File "/py/lib/python3.9/site-packages/django/urls/resolvers.py", line 698, in _reverse_with_prefix
    raise NoReverseMatch(msg)
django.urls.exceptions.NoReverseMatch: Reverse for 'core_user_chagelist' not found. 'core_user_chagelist' is not a valid view function or pattern name.

----------------------------------------------------------------------
Ran 9 tests in 0.656s

FAILED (errors=1)
Destroying test database for alias 'default'...
```