```python
"""
Django admin customization
"""
from django.contrib import admin
from django.contrib.auth.admin import UserAdmin as BaseUserAdmin

from core import models

  
class UserAdmin(BaseUserAdmin):
    """Define the admin Pages for users."""
    ordering = ['id']
    list_display = ['email', 'name']

admin.site.register(models.User, UserAdmin)
```

```bash
$ docker-compose run --rm app sh -c "python manage.py test"
[+] Running 1/0
 - Container api-prac-db-1  Running                     0.0s 
Creating test database for alias 'default'...
System check identified no issues (0 silenced).
.......Waitng for database ...
Database unvailable, waiting 1 second ...
Database unvailable, waiting 1 second ...
Database unvailable, waiting 1 second ...
Database unvailable, waiting 1 second ...
Database unvailable, waiting 1 second ...
Database available !
.Waitng for database ...
Database available !
.
----------------------------------------------------------------------
Ran 9 tests in 0.695s

OK
Destroying test database for alias 'default'...
```

![[Pasted image 20221115114813.png]]

```python
    def test_edit_user_page(self):
        """Test the edit user page works."""
        url = reverse('admin:core_user_change', args=[self.user.id])
        res = self.client.get(url)

        self.assertEqual(res.status_code, 200)
```

```bash
$ docker-compose run --rm app sh -c "python manage.py test"
[+] Running 1/0
 - Container api-prac-db-1  Running                     0.0s 
Creating test database for alias 'default'...
System check identified no issues (0 silenced).
E.......Waitng for database ...
Database unvailable, waiting 1 second ...
Database unvailable, waiting 1 second ...
Database unvailable, waiting 1 second ...
Database unvailable, waiting 1 second ...
Database unvailable, waiting 1 second ...
Database available !
.Waitng for database ...
Database available !
.
======================================================================
ERROR: test_edit_user_page (core.tests.test_admin.AdminSiteTests)
Test the edit user page works.
----------------------------------------------------------------------
Traceback (most recent call last):
  File "/py/lib/python3.9/site-packages/django/contrib/admin/options.py", line 710, in get_form
    return modelform_factory(self.model, **defaults)
  File "/py/lib/python3.9/site-packages/django/forms/models.py", line 563, in modelform_factory
    return type(form)(class_name, (form,), form_class_attrs) 
  File "/py/lib/python3.9/site-packages/django/forms/models.py", line 276, in __new__
    raise FieldError(message)
django.core.exceptions.FieldError: Unknown field(s) (last_name, username, first_name, date_joined) specified for User     

During handling of the above exception, another exception occurred:

Traceback (most recent call last):
  File "/app/core/tests/test_admin.py", line 38, in test_edit_user_page
    res = self.client.get(url)
  File "/py/lib/python3.9/site-packages/django/test/client.py", line 742, in get
    response = super().get(path, data=data, secure=secure, **extra)
  File "/py/lib/python3.9/site-packages/django/test/client.py", line 396, in get
    return self.generic('GET', path, secure=secure, **{      
  File "/py/lib/python3.9/site-packages/django/test/client.py", line 473, in generic
    return self.request(**r)
  File "/py/lib/python3.9/site-packages/django/test/client.py", line 719, in request
    self.check_exception(response)
  File "/py/lib/python3.9/site-packages/django/test/client.py", line 580, in check_exception
    raise exc_value
  File "/py/lib/python3.9/site-packages/django/core/handlers/exception.py", line 47, in inner
    response = get_response(request)
  File "/py/lib/python3.9/site-packages/django/core/handlers/base.py", line 181, in _get_response
    response = wrapped_callback(request, *callback_args, **callback_kwargs)
  File "/py/lib/python3.9/site-packages/django/contrib/admin/options.py", line 616, in wrapper
    return self.admin_site.admin_view(view)(*args, **kwargs) 
  File "/py/lib/python3.9/site-packages/django/utils/decorators.py", line 130, in _wrapped_view
    response = view_func(request, *args, **kwargs)
  File "/py/lib/python3.9/site-packages/django/views/decorators/cache.py", line 44, in _wrapped_view_func
    response = view_func(request, *args, **kwargs)
  File "/py/lib/python3.9/site-packages/django/contrib/admin/sites.py", line 232, in inner
    return view(request, *args, **kwargs)
  File "/py/lib/python3.9/site-packages/django/contrib/admin/options.py", line 1660, in change_view
    return self.changeform_view(request, object_id, form_url, extra_context)
  File "/py/lib/python3.9/site-packages/django/utils/decorators.py", line 43, in _wrapper
    return bound_method(*args, **kwargs)
  File "/py/lib/python3.9/site-packages/django/utils/decorators.py", line 130, in _wrapped_view
    response = view_func(request, *args, **kwargs)
  File "/py/lib/python3.9/site-packages/django/contrib/admin/options.py", line 1540, in changeform_view
    return self._changeform_view(request, object_id, form_url, extra_context)
  File "/py/lib/python3.9/site-packages/django/contrib/admin/options.py", line 1574, in _changeform_view
    ModelForm = self.get_form(
  File "/py/lib/python3.9/site-packages/django/contrib/auth/admin.py", line 80, in get_form
    return super().get_form(request, obj, **defaults)        
  File "/py/lib/python3.9/site-packages/django/contrib/admin/options.py", line 712, in get_form
    raise FieldError(
django.core.exceptions.FieldError: Unknown field(s) (last_name, username, first_name, date_joined) specified for User. Check fields/fieldsets/exclude attributes of class UserAdmin.   

----------------------------------------------------------------------
Ran 10 tests in 0.908s

FAILED (errors=1)
Destroying test database for alias 'default'...

```


```python
"""
Django admin customization
"""
from django.contrib import admin
from django.contrib.auth.admin import UserAdmin as BaseUserAdmin
from django.utils.translation import gettext_lazy as _

from core import models


class UserAdmin(BaseUserAdmin):
    """Define the admin Pages for users."""

    ordering = ['id']
    list_display = ['email', 'name']
    fieldsets = (
        (None, {'fields': ('email', 'password')}),
        (
            _('Permissions'),
            {
                'fields': (
                    'is_active',
                    'is_staff',
                    'is_superuser',
                )
            }
        ),
        (_('Important dates'), {'fields':('last_login',)}),
    )

    readonly_fields = ['last_login']

admin.site.register(models.User, UserAdmin)
```

```bash
$ docker-compose run --rm app sh -c "python manage.py test"
[+] Running 1/0
 - Container api-prac-db-1  Running                     0.0s 
Creating test database for alias 'default'...
System check identified no issues (0 silenced).
........Waitng for database ...
Database unvailable, waiting 1 second ...
Database unvailable, waiting 1 second ...
Database unvailable, waiting 1 second ...
Database unvailable, waiting 1 second ...
Database unvailable, waiting 1 second ...
Database available !
.Waitng for database ...
Database available !
.
----------------------------------------------------------------------
Ran 10 tests in 0.849s

OK
Destroying test database for alias 'default'...
(base) 
```