```python
    def test_create_token_for_user(self):
        """Test generates token for valid credentials"""
        user_detail = {
            'name': 'Test Name',
            'email': 'test@example.com',
            'password': 'test-user-password123',
        }
        create_user(**user_detail)

        payload = {
            'email': user_detail['email'],
            'password': user_detail['password']
        }

        res = self.client.post(TOKEN_URL, payload)

        self.assertIn('token', res.data)
        self.assertEqual(res.status_code, status.HTTP_200_OK)

    def test_create_token_bad_credentials(self):
        """Test returns error if credentials invalid."""
        create_user(email='test@example.com', password='goodpass')
  
        payload = {'email': 'test@example.com', 'password': 'badpass'}
        res = self.client.post(TOKEN_URL, payload)

        self.assertNotIn('token', res.data)
        self.assertEqual(res.status_code, status.HTTP_400_BAD_REQUEST)


    def test_create_token_blank_password(self):
        """Test posting a blank password returns an error."""
        payload = {'email': 'test@example.com','password': ''}
        res = self.client.post(TOKEN_URL, payload)
  

        self.assertNotIn('token', res.data)
        self.assertEqual(res.status_code, status.HTTP_400_BAD_REQUEST)

```

```bash
$ docker-compose run --rm app sh -c "python manage.py test"
[+] Running 1/0
 - Container api-prac-db-1  Running                      0.0s 
Creating test database for alias 'default'...
System check identified no issues (0 silenced).
.........Waitng for database ...
Database unvailable, waiting 1 second ...
Database unvailable, waiting 1 second ...
Database unvailable, waiting 1 second ...
Database unvailable, waiting 1 second ...
Database unvailable, waiting 1 second ...
Database available !
.Waitng for database ...
Database available !
.E
======================================================================
ERROR: user.tests.test_user_api (unittest.loader._FailedTest) 
----------------------------------------------------------------------
ImportError: Failed to import test module: user.tests.test_user_api
Traceback (most recent call last):
  File "/usr/local/lib/python3.9/unittest/loader.py", line 436, in _find_test_path
    module = self._get_module_from_name(name)
  File "/usr/local/lib/python3.9/unittest/loader.py", line 377, in _get_module_from_name
    __import__(name)
  File "/app/user/tests/test_user_api.py", line 13, in <module>
    TOKEN_URL = reverse('user:token')
  File "/py/lib/python3.9/site-packages/django/urls/base.py", line 86, in reverse
    return resolver._reverse_with_prefix(view, prefix, *args, **kwargs)
  File "/py/lib/python3.9/site-packages/django/urls/resolvers.py", line 698, in _reverse_with_prefix
    raise NoReverseMatch(msg)
django.urls.exceptions.NoReverseMatch: Reverse for 'token' not found. 'token' is not a valid view function or pattern name. 


----------------------------------------------------------------------
Ran 12 tests in 1.009s

FAILED (errors=1)
Destroying test database for alias 'default'...
```